Workbook

Sheet CRM
A1: nombre_gestoria | B1: ciudad | C1: provincia | D1: web | E1: telefono | F1: email | G1: direccion | H1: tier | I1: calidez | J1: encaje | K1: fuente | L1: notas | M1: estado | N1: fecha_contacto | O1: canal_contacto | P1: num_toques | Q1: respuesta | R1: fecha_respuesta | S1: reunion_agendada | T1: demo_realizada | U1: piloto_aceptado | V1: rechazo | W1: motivo_rechazo | X1: ficha_feedback | Y1: proxima_accion | Z1: fecha_proxima_accion | AA1: cliente_pago | AB1: mrr_eur | AC1: dias_desde_contacto | AD1: accion_sugerida_hoy
A2: Gestoría AVANZA | B2: Valencia | C2: Valencia | H2: A | I2: frío | J2: alto | K2: Búsqueda web 2026-07-11 | L2: 4.80/5 en 104 reseñas, asesoría integral fiscal/jurídica/contable/laboral para pymes y autónomos | M2: pendiente_contacto | Y2: Verificar teléfono/email en su web antes de contactar | AC2: =IF(N2="","",TODAY()-N2) | AD2: =IF(N2="","Contactar (día 0)",IF(OR(Q2="sí",M2="rechazado",M2="cliente_pago",M2="sin_respuesta"),"",IF(AND(P2<=1,AC2>=3),"Seguimiento 1 (mismo canal)",IF(AND(P2<=2,AC2>=7),"Seguimiento 2 (canal distinto)",IF(AND(P2<=3,AC2>=12),"Seguimiento 3 (último, ofrece cerrar la puerta)",IF(OR(P2>=4,AC2>=15),"Cerrar: marcar sin-respuesta",""))))))
A3: Gestoría Pastor | B3: Valencia | C3: Valencia | H3: B | I3: frío | J3: medio | K3: Búsqueda web 2026-07-11 | L3: Más de 95 años de trayectoria, atiende pymes, medianas y grandes empresas — puede ser más institucional de lo ideal para el piloto | M3: pendiente_contacto | Y3: Verificar teléfono/email en su web antes de contactar | AC3: =IF(N3="","",TODAY()-N3) | AD3: =IF(N3="","Contactar (día 0)",IF(OR(Q3="sí",M3="rechazado",M3="cliente_pago",M3="sin_respuesta"),"",IF(AND(P3<=1,AC3>=3),"Seguimiento 1 (mismo canal)",IF(AND(P3<=2,AC3>=7),"Seguimiento 2 (canal distinto)",IF(AND(P3<=3,AC3>=12),"Seguimiento 3 (último, ofrece cerrar la puerta)",IF(OR(P3>=4,AC3>=15),"Cerrar: marcar sin-respuesta",""))))))
A4: Asesoría Autónomos Valencia | B4: Valencia | C4: Valencia | D4: asesoriaautonomosvalencia.com | H4: A | I4: frío | J4: alto | K4: Búsqueda web 2026-07-11 | L4: Más de 20 años especializados en autónomos, servicio presencial y online | M4: pendiente_contacto | Y4: Verificar email en su web antes de contactar | AC4: =IF(N4="","",TODAY()-N4) | AD4: =IF(N4="","Contactar (día 0)",IF(OR(Q4="sí",M4="rechazado",M4="cliente_pago",M4="sin_respuesta"),"",IF(AND(P4<=1,AC4>=3),"Seguimiento 1 (mismo canal)",IF(AND(P4<=2,AC4>=7),"Seguimiento 2 (canal distinto)",IF(AND(P4<=3,AC4>=12),"Seguimiento 3 (último, ofrece cerrar la puerta)",IF(OR(P4>=4,AC4>=15),"Cerrar: marcar sin-respuesta",""))))))
A5: Gestoría Autónomos Barcelona | B5: L'Hospitalet de Llobregat | C5: Barcelona | D5: gestoriaautonomosbarcelona.com | H5: A | I5: frío | J5: alto | K5: Búsqueda web 2026-07-11 | L5: 13 años, especializada en autónomos, cuota 60€+IVA/mes, oficina a 5 min del centro de Barcelona | M5: pendiente_contacto | Y5: Verificar email en su web antes de contactar | AC5: =IF(N5="","",TODAY()-N5) | AD5: =IF(N5="","Contactar (día 0)",IF(OR(Q5="sí",M5="rechazado",M5="cliente_pago",M5="sin_respuesta"),"",IF(AND(P5<=1,AC5>=3),"Seguimiento 1 (mismo canal)",IF(AND(P5<=2,AC5>=7),"Seguimiento 2 (canal distinto)",IF(AND(P5<=3,AC5>=12),"Seguimiento 3 (último, ofrece cerrar la puerta)",IF(OR(P5>=4,AC5>=15),"Cerrar: marcar sin-respuesta",""))))))
A6: Gestoría Barcelona | B6: Barcelona | C6: Barcelona | D6: gestoriabarcelona.cat | H6: B | I6: frío | J6: medio | K6: Búsqueda web 2026-07-11 | L6: Asesoría integral fiscal/laboral/financiera/contable/jurídica | M6: pendiente_contacto | Y6: Verificar email en su web antes de contactar | AC6: =IF(N6="","",TODAY()-N6) | AD6: =IF(N6="","Contactar (día 0)",IF(OR(Q6="sí",M6="rechazado",M6="cliente_pago",M6="sin_respuesta"),"",IF(AND(P6<=1,AC6>=3),"Seguimiento 1 (mismo canal)",IF(AND(P6<=2,AC6>=7),"Seguimiento 2 (canal distinto)",IF(AND(P6<=3,AC6>=12),"Seguimiento 3 (último, ofrece cerrar la puerta)",IF(OR(P6>=4,AC6>=15),"Cerrar: marcar sin-respuesta",""))))))
A7: DAEM | B7: Barcelona / Sabadell | C7: Barcelona | H7: A | I7: frío | J7: alto | K7: Búsqueda web 2026-07-11 | L7: Oficinas en Barcelona y Sabadell, acompañamiento cercano a empresas y autónomos | M7: pendiente_contacto | Y7: Verificar teléfono/email en su web antes de contactar | AC7: =IF(N7="","",TODAY()-N7) | AD7: =IF(N7="","Contactar (día 0)",IF(OR(Q7="sí",M7="rechazado",M7="cliente_pago",M7="sin_respuesta"),"",IF(AND(P7<=1,AC7>=3),"Seguimiento 1 (mismo canal)",IF(AND(P7<=2,AC7>=7),"Seguimiento 2 (canal distinto)",IF(AND(P7<=3,AC7>=12),"Seguimiento 3 (último, ofrece cerrar la puerta)",IF(OR(P7>=4,AC7>=15),"Cerrar: marcar sin-respuesta",""))))))
A8: MLT Asesores | B8: Barcelona | C8: Barcelona | D8: mltasesores.com | H8: A | I8: frío | J8: alto | K8: Búsqueda web 2026-07-11 | L8: Cuota mensual de gestión fiscal/contable/laboral centrada en autónomos | M8: pendiente_contacto | Y8: Verificar email en su web antes de contactar | AC8: =IF(N8="","",TODAY()-N8) | AD8: =IF(N8="","Contactar (día 0)",IF(OR(Q8="sí",M8="rechazado",M8="cliente_pago",M8="sin_respuesta"),"",IF(AND(P8<=1,AC8>=3),"Seguimiento 1 (mismo canal)",IF(AND(P8<=2,AC8>=7),"Seguimiento 2 (canal distinto)",IF(AND(P8<=3,AC8>=12),"Seguimiento 3 (último, ofrece cerrar la puerta)",IF(OR(P8>=4,AC8>=15),"Cerrar: marcar sin-respuesta",""))))))
A9: Assessoria Despí S.L. | B9: Barcelona | C9: Barcelona | H9: A | I9: frío | J9: alto | K9: Búsqueda web 2026-07-11 | L9: Desde 1991, especializada en autónomos y pequeñas empresas | M9: pendiente_contacto | Y9: Verificar teléfono/email en su web antes de contactar | AC9: =IF(N9="","",TODAY()-N9) | AD9: =IF(N9="","Contactar (día 0)",IF(OR(Q9="sí",M9="rechazado",M9="cliente_pago",M9="sin_respuesta"),"",IF(AND(P9<=1,AC9>=3),"Seguimiento 1 (mismo canal)",IF(AND(P9<=2,AC9>=7),"Seguimiento 2 (canal distinto)",IF(AND(P9<=3,AC9>=12),"Seguimiento 3 (último, ofrece cerrar la puerta)",IF(OR(P9>=4,AC9>=15),"Cerrar: marcar sin-respuesta",""))))))
A10: La Gestoría Online | B10: Sevilla | C10: Sevilla | E10: 621271992 | H10: B | I10: frío | J10: medio | K10: Búsqueda web 2026-07-11 | L10: Modelo principalmente online | M10: pendiente_contacto | Y10: Llamar o WhatsApp al teléfono verificado | AC10: =IF(N10="","",TODAY()-N10) | AD10: =IF(N10="","Contactar (día 0)",IF(OR(Q10="sí",M10="rechazado",M10="cliente_pago",M10="sin_respuesta"),"",IF(AND(P10<=1,AC10>=3),"Seguimiento 1 (mismo canal)",IF(AND(P10<=2,AC10>=7),"Seguimiento 2 (canal distinto)",IF(AND(P10<=3,AC10>=12),"Seguimiento 3 (último, ofrece cerrar la puerta)",IF(OR(P10>=4,AC10>=15),"Cerrar: marcar sin-respuesta",""))))))
A11: Activa Consultores | B11: Sevilla | C11: Sevilla | G11: C/ Asunción, 80, 11ºB, 41011 Sevilla | H11: B | I11: frío | J11: medio | K11: Búsqueda web 2026-07-11 | M11: pendiente_contacto | Y11: Verificar teléfono/email en su web antes de contactar | AC11: =IF(N11="","",TODAY()-N11) | AD11: =IF(N11="","Contactar (día 0)",IF(OR(Q11="sí",M11="rechazado",M11="cliente_pago",M11="sin_respuesta"),"",IF(AND(P11<=1,AC11>=3),"Seguimiento 1 (mismo canal)",IF(AND(P11<=2,AC11>=7),"Seguimiento 2 (canal distinto)",IF(AND(P11<=3,AC11>=12),"Seguimiento 3 (último, ofrece cerrar la puerta)",IF(OR(P11>=4,AC11>=15),"Cerrar: marcar sin-respuesta",""))))))
A12: Zamorano Cruz Asesores | B12: Sevilla | C12: Sevilla | G12: Av. de la República Argentina, 27 B, 2º I, 41011 Sevilla | H12: B | I12: frío | J12: medio | K12: Búsqueda web 2026-07-11 | M12: pendiente_contacto | Y12: Verificar teléfono/email en su web antes de contactar | AC12: =IF(N12="","",TODAY()-N12) | AD12: =IF(N12="","Contactar (día 0)",IF(OR(Q12="sí",M12="rechazado",M12="cliente_pago",M12="sin_respuesta"),"",IF(AND(P12<=1,AC12>=3),"Seguimiento 1 (mismo canal)",IF(AND(P12<=2,AC12>=7),"Seguimiento 2 (canal distinto)",IF(AND(P12<=3,AC12>=12),"Seguimiento 3 (último, ofrece cerrar la puerta)",IF(OR(P12>=4,AC12>=15),"Cerrar: marcar sin-respuesta",""))))))
A13: Fisconlab | B13: Sevilla | C13: Sevilla | G13: C. Arquitectura, 3, Torre 7, Planta 10, 41015 Sevilla | H13: B | I13: frío | J13: medio | K13: Búsqueda web 2026-07-11 | M13: pendiente_contacto | Y13: Verificar teléfono/email en su web antes de contactar | AC13: =IF(N13="","",TODAY()-N13) | AD13: =IF(N13="","Contactar (día 0)",IF(OR(Q13="sí",M13="rechazado",M13="cliente_pago",M13="sin_respuesta"),"",IF(AND(P13<=1,AC13>=3),"Seguimiento 1 (mismo canal)",IF(AND(P13<=2,AC13>=7),"Seguimiento 2 (canal distinto)",IF(AND(P13<=3,AC13>=12),"Seguimiento 3 (último, ofrece cerrar la puerta)",IF(OR(P13>=4,AC13>=15),"Cerrar: marcar sin-respuesta",""))))))
A14: Sevitia | B14: Sevilla | C14: Sevilla | D14: sevitia.com | E14: 644980526 | F14: info@sevitia.com | H14: A | I14: frío | J14: alto | K14: Búsqueda web 2026-07-11 | L14: Gestoría para autónomos y emprendedores | M14: pendiente_contacto | Y14: Contactar por email o WhatsApp | AC14: =IF(N14="","",TODAY()-N14) | AD14: =IF(N14="","Contactar (día 0)",IF(OR(Q14="sí",M14="rechazado",M14="cliente_pago",M14="sin_respuesta"),"",IF(AND(P14<=1,AC14>=3),"Seguimiento 1 (mismo canal)",IF(AND(P14<=2,AC14>=7),"Seguimiento 2 (canal distinto)",IF(AND(P14<=3,AC14>=12),"Seguimiento 3 (último, ofrece cerrar la puerta)",IF(OR(P14>=4,AC14>=15),"Cerrar: marcar sin-respuesta",""))))))
A15: GesDogma | B15: Sevilla | C15: Sevilla | D15: gesdogma.com | E15: 659821233 | H15: A | I15: frío | J15: alto | K15: Búsqueda web 2026-07-11 | L15: Asesoría para autónomos y empresas | M15: pendiente_contacto | Y15: Llamar o WhatsApp al teléfono verificado | AC15: =IF(N15="","",TODAY()-N15) | AD15: =IF(N15="","Contactar (día 0)",IF(OR(Q15="sí",M15="rechazado",M15="cliente_pago",M15="sin_respuesta"),"",IF(AND(P15<=1,AC15>=3),"Seguimiento 1 (mismo canal)",IF(AND(P15<=2,AC15>=7),"Seguimiento 2 (canal distinto)",IF(AND(P15<=3,AC15>=12),"Seguimiento 3 (último, ofrece cerrar la puerta)",IF(OR(P15>=4,AC15>=15),"Cerrar: marcar sin-respuesta",""))))))
A16: GVV Asesores y Consultores | B16: Sevilla | C16: Sevilla | D16: consulgvv.es | E16: 954238171 | H16: B | I16: frío | J16: medio | K16: Búsqueda web 2026-07-11 | M16: pendiente_contacto | Y16: Llamar al teléfono verificado | AC16: =IF(N16="","",TODAY()-N16) | AD16: =IF(N16="","Contactar (día 0)",IF(OR(Q16="sí",M16="rechazado",M16="cliente_pago",M16="sin_respuesta"),"",IF(AND(P16<=1,AC16>=3),"Seguimiento 1 (mismo canal)",IF(AND(P16<=2,AC16>=7),"Seguimiento 2 (canal distinto)",IF(AND(P16<=3,AC16>=12),"Seguimiento 3 (último, ofrece cerrar la puerta)",IF(OR(P16>=4,AC16>=15),"Cerrar: marcar sin-respuesta",""))))))
A17: Gestoría Miguel Mayal Sevilla Este | B17: Sevilla | C17: Sevilla | E17: 954675869 | H17: B | I17: frío | J17: medio | K17: Búsqueda web 2026-07-11 | M17: pendiente_contacto | Y17: Llamar al teléfono verificado | AC17: =IF(N17="","",TODAY()-N17) | AD17: =IF(N17="","Contactar (día 0)",IF(OR(Q17="sí",M17="rechazado",M17="cliente_pago",M17="sin_respuesta"),"",IF(AND(P17<=1,AC17>=3),"Seguimiento 1 (mismo canal)",IF(AND(P17<=2,AC17>=7),"Seguimiento 2 (canal distinto)",IF(AND(P17<=3,AC17>=12),"Seguimiento 3 (último, ofrece cerrar la puerta)",IF(OR(P17>=4,AC17>=15),"Cerrar: marcar sin-respuesta",""))))))
A18: Centro de Gestión | B18: Zaragoza | C18: Zaragoza | D18: centrodegestion.com | E18: 876008400 | F18: info@centrodegestion.com | G18: Calle Cinco de Marzo 14, 2º B, 50004 Zaragoza | H18: A | I18: frío | J18: alto | K18: Búsqueda web 2026-07-11 | M18: pendiente_contacto | Y18: Contactar por email o teléfono | AC18: =IF(N18="","",TODAY()-N18) | AD18: =IF(N18="","Contactar (día 0)",IF(OR(Q18="sí",M18="rechazado",M18="cliente_pago",M18="sin_respuesta"),"",IF(AND(P18<=1,AC18>=3),"Seguimiento 1 (mismo canal)",IF(AND(P18<=2,AC18>=7),"Seguimiento 2 (canal distinto)",IF(AND(P18<=3,AC18>=12),"Seguimiento 3 (último, ofrece cerrar la puerta)",IF(OR(P18>=4,AC18>=15),"Cerrar: marcar sin-respuesta",""))))))
A19: Gestoría Independencia | B19: Zaragoza | C19: Zaragoza | D19: gestoriaindependencia27.es | E19: 976112689 | H19: A | I19: frío | J19: alto | K19: Búsqueda web 2026-07-11 | M19: pendiente_contacto | Y19: Llamar al teléfono verificado | AC19: =IF(N19="","",TODAY()-N19) | AD19: =IF(N19="","Contactar (día 0)",IF(OR(Q19="sí",M19="rechazado",M19="cliente_pago",M19="sin_respuesta"),"",IF(AND(P19<=1,AC19>=3),"Seguimiento 1 (mismo canal)",IF(AND(P19<=2,AC19>=7),"Seguimiento 2 (canal distinto)",IF(AND(P19<=3,AC19>=12),"Seguimiento 3 (último, ofrece cerrar la puerta)",IF(OR(P19>=4,AC19>=15),"Cerrar: marcar sin-respuesta",""))))))
A20: Aragonia Asesores Asociados | B20: Zaragoza | C20: Zaragoza | D20: aragonia-asesores.es | E20: 976220145 | F20: aragonia@economistas.org | G20: Gran Vía 30, Local, Zaragoza | H20: B | I20: frío | J20: medio | K20: Búsqueda web 2026-07-11 | L20: Vinculada a economistas colegiados | M20: pendiente_contacto | Y20: Contactar por email o teléfono | AC20: =IF(N20="","",TODAY()-N20) | AD20: =IF(N20="","Contactar (día 0)",IF(OR(Q20="sí",M20="rechazado",M20="cliente_pago",M20="sin_respuesta"),"",IF(AND(P20<=1,AC20>=3),"Seguimiento 1 (mismo canal)",IF(AND(P20<=2,AC20>=7),"Seguimiento 2 (canal distinto)",IF(AND(P20<=3,AC20>=12),"Seguimiento 3 (último, ofrece cerrar la puerta)",IF(OR(P20>=4,AC20>=15),"Cerrar: marcar sin-respuesta",""))))))
A21: Asesoría Ligorred | B21: Zaragoza | C21: Zaragoza | D21: asesorialigorred.es | E21: 976259950 | H21: A | I21: frío | J21: alto | K21: Búsqueda web 2026-07-11 | L21: Especializada en autónomos | M21: pendiente_contacto | Y21: Llamar al teléfono verificado | AC21: =IF(N21="","",TODAY()-N21) | AD21: =IF(N21="","Contactar (día 0)",IF(OR(Q21="sí",M21="rechazado",M21="cliente_pago",M21="sin_respuesta"),"",IF(AND(P21<=1,AC21>=3),"Seguimiento 1 (mismo canal)",IF(AND(P21<=2,AC21>=7),"Seguimiento 2 (canal distinto)",IF(AND(P21<=3,AC21>=12),"Seguimiento 3 (último, ofrece cerrar la puerta)",IF(OR(P21>=4,AC21>=15),"Cerrar: marcar sin-respuesta",""))))))
A22: Asesoría AM Zaragoza | B22: Zaragoza | C22: Zaragoza | D22: asesoriaamzaragoza.es | E22: 976004971 | G22: Plaza Salamero, 14, 2B, 50004 Zaragoza | H22: B | I22: frío | J22: medio | K22: Búsqueda web 2026-07-11 | M22: pendiente_contacto | Y22: Llamar al teléfono verificado | AC22: =IF(N22="","",TODAY()-N22) | AD22: =IF(N22="","Contactar (día 0)",IF(OR(Q22="sí",M22="rechazado",M22="cliente_pago",M22="sin_respuesta"),"",IF(AND(P22<=1,AC22>=3),"Seguimiento 1 (mismo canal)",IF(AND(P22<=2,AC22>=7),"Seguimiento 2 (canal distinto)",IF(AND(P22<=3,AC22>=12),"Seguimiento 3 (último, ofrece cerrar la puerta)",IF(OR(P22>=4,AC22>=15),"Cerrar: marcar sin-respuesta",""))))))
A23: ASEM | B23: Zaragoza | C23: Zaragoza | D23: asem.es | G23: Calle San Vicente Paúl 25, pral. dcha, 50001 Zaragoza | H23: B | I23: frío | J23: medio | K23: Búsqueda web 2026-07-11 | M23: pendiente_contacto | Y23: Verificar teléfono/email en su web antes de contactar | AC23: =IF(N23="","",TODAY()-N23) | AD23: =IF(N23="","Contactar (día 0)",IF(OR(Q23="sí",M23="rechazado",M23="cliente_pago",M23="sin_respuesta"),"",IF(AND(P23<=1,AC23>=3),"Seguimiento 1 (mismo canal)",IF(AND(P23<=2,AC23>=7),"Seguimiento 2 (canal distinto)",IF(AND(P23<=3,AC23>=12),"Seguimiento 3 (último, ofrece cerrar la puerta)",IF(OR(P23>=4,AC23>=15),"Cerrar: marcar sin-respuesta",""))))))
A24: Gestoría Esteban & Domínguez | B24: Zaragoza | C24: Zaragoza | D24: gestoriaszaragoza.com | E24: 976383035 | F24: administracion@gestoriaszaragoza.com | G24: Urb. Paraíso, 4, Zaragoza | H24: B | I24: frío | J24: medio | K24: Búsqueda web 2026-07-11 | M24: pendiente_contacto | Y24: Contactar por email o teléfono | AC24: =IF(N24="","",TODAY()-N24) | AD24: =IF(N24="","Contactar (día 0)",IF(OR(Q24="sí",M24="rechazado",M24="cliente_pago",M24="sin_respuesta"),"",IF(AND(P24<=1,AC24>=3),"Seguimiento 1 (mismo canal)",IF(AND(P24<=2,AC24>=7),"Seguimiento 2 (canal distinto)",IF(AND(P24<=3,AC24>=12),"Seguimiento 3 (último, ofrece cerrar la puerta)",IF(OR(P24>=4,AC24>=15),"Cerrar: marcar sin-respuesta",""))))))
A25: Asesoría Aldaba | B25: Málaga | C25: Málaga | D25: asesoriaaldaba.com | E25: 951829957 | F25: info@asesoriaaldaba.com | G25: C/ Ferrocarril del Puerto, 6, local E, 29002 Málaga | H25: A | I25: frío | J25: alto | K25: Búsqueda web 2026-07-11 | M25: pendiente_contacto | Y25: Contactar por email o teléfono | AC25: =IF(N25="","",TODAY()-N25) | AD25: =IF(N25="","Contactar (día 0)",IF(OR(Q25="sí",M25="rechazado",M25="cliente_pago",M25="sin_respuesta"),"",IF(AND(P25<=1,AC25>=3),"Seguimiento 1 (mismo canal)",IF(AND(P25<=2,AC25>=7),"Seguimiento 2 (canal distinto)",IF(AND(P25<=3,AC25>=12),"Seguimiento 3 (último, ofrece cerrar la puerta)",IF(OR(P25>=4,AC25>=15),"Cerrar: marcar sin-respuesta",""))))))
A26: GesTORÉ | B26: Málaga | C26: Málaga | D26: tore.es | H26: A | I26: frío | J26: alto | K26: Búsqueda web 2026-07-11 | L26: Atención en oficina, teléfono o WhatsApp | M26: pendiente_contacto | Y26: Verificar teléfono/email en su web antes de contactar | AC26: =IF(N26="","",TODAY()-N26) | AD26: =IF(N26="","Contactar (día 0)",IF(OR(Q26="sí",M26="rechazado",M26="cliente_pago",M26="sin_respuesta"),"",IF(AND(P26<=1,AC26>=3),"Seguimiento 1 (mismo canal)",IF(AND(P26<=2,AC26>=7),"Seguimiento 2 (canal distinto)",IF(AND(P26<=3,AC26>=12),"Seguimiento 3 (último, ofrece cerrar la puerta)",IF(OR(P26>=4,AC26>=15),"Cerrar: marcar sin-respuesta",""))))))
A27: Gestoría Rubén María | B27: Multi-ciudad (Málaga/Alicante/Murcia/Valladolid/A Coruña/Bilbao) | C27: Varias | D27: gestoriarubenmaria.es | E27: 620001166 | H27: C | I27: frío | J27: bajo | K27: Búsqueda web 2026-07-11 | L27: Aparece en varias ciudades — probable operación online multi-oficina, menos prioritaria como piloto por ya estar digitalizada | M27: pendiente_contacto | Y27: Baja prioridad — considerar solo si faltan prospectos | AC27: =IF(N27="","",TODAY()-N27) | AD27: =IF(N27="","Contactar (día 0)",IF(OR(Q27="sí",M27="rechazado",M27="cliente_pago",M27="sin_respuesta"),"",IF(AND(P27<=1,AC27>=3),"Seguimiento 1 (mismo canal)",IF(AND(P27<=2,AC27>=7),"Seguimiento 2 (canal distinto)",IF(AND(P27<=3,AC27>=12),"Seguimiento 3 (último, ofrece cerrar la puerta)",IF(OR(P27>=4,AC27>=15),"Cerrar: marcar sin-respuesta",""))))))
A28: Proasa | B28: Málaga | C28: Málaga | D28: proasa.org | E28: 952364229 | G28: Po. La Alameda C/Nabucco I-6, 29006 Málaga | H28: B | I28: frío | J28: medio | K28: Búsqueda web 2026-07-11 | M28: pendiente_contacto | Y28: Llamar al teléfono verificado | AC28: =IF(N28="","",TODAY()-N28) | AD28: =IF(N28="","Contactar (día 0)",IF(OR(Q28="sí",M28="rechazado",M28="cliente_pago",M28="sin_respuesta"),"",IF(AND(P28<=1,AC28>=3),"Seguimiento 1 (mismo canal)",IF(AND(P28<=2,AC28>=7),"Seguimiento 2 (canal distinto)",IF(AND(P28<=3,AC28>=12),"Seguimiento 3 (último, ofrece cerrar la puerta)",IF(OR(P28>=4,AC28>=15),"Cerrar: marcar sin-respuesta",""))))))
A29: Asesoría de Autónomos AF | B29: Málaga | C29: Málaga | D29: asesoriaautonomos-af.es | E29: 952369200 | H29: A | I29: frío | J29: alto | K29: Búsqueda web 2026-07-11 | M29: pendiente_contacto | Y29: Llamar al teléfono verificado | AC29: =IF(N29="","",TODAY()-N29) | AD29: =IF(N29="","Contactar (día 0)",IF(OR(Q29="sí",M29="rechazado",M29="cliente_pago",M29="sin_respuesta"),"",IF(AND(P29<=1,AC29>=3),"Seguimiento 1 (mismo canal)",IF(AND(P29<=2,AC29>=7),"Seguimiento 2 (canal distinto)",IF(AND(P29<=3,AC29>=12),"Seguimiento 3 (último, ofrece cerrar la puerta)",IF(OR(P29>=4,AC29>=15),"Cerrar: marcar sin-respuesta",""))))))
A30: Asesor Autónomos Málaga | B30: Málaga | C30: Málaga | D30: asesorautonomosmalaga.es | G30: Centro histórico de Málaga | H30: A | I30: frío | J30: alto | K30: Búsqueda web 2026-07-11 | M30: pendiente_contacto | Y30: Verificar teléfono/email en su web antes de contactar | AC30: =IF(N30="","",TODAY()-N30) | AD30: =IF(N30="","Contactar (día 0)",IF(OR(Q30="sí",M30="rechazado",M30="cliente_pago",M30="sin_respuesta"),"",IF(AND(P30<=1,AC30>=3),"Seguimiento 1 (mismo canal)",IF(AND(P30<=2,AC30>=7),"Seguimiento 2 (canal distinto)",IF(AND(P30<=3,AC30>=12),"Seguimiento 3 (último, ofrece cerrar la puerta)",IF(OR(P30>=4,AC30>=15),"Cerrar: marcar sin-respuesta",""))))))
A31: Gesfiser Ibr | B31: Bilbao | C31: Bizkaia | D31: gesfiser.es | E31: 944474072 | F31: info@gesfiser.es | G31: C/ Barroeta Aldamar 4, planta 4, Dpto. 41, 48001 Bilbao | H31: A | I31: frío | J31: alto | K31: Búsqueda web 2026-07-11 | M31: pendiente_contacto | Y31: Contactar por email o teléfono | AC31: =IF(N31="","",TODAY()-N31) | AD31: =IF(N31="","Contactar (día 0)",IF(OR(Q31="sí",M31="rechazado",M31="cliente_pago",M31="sin_respuesta"),"",IF(AND(P31<=1,AC31>=3),"Seguimiento 1 (mismo canal)",IF(AND(P31<=2,AC31>=7),"Seguimiento 2 (canal distinto)",IF(AND(P31<=3,AC31>=12),"Seguimiento 3 (último, ofrece cerrar la puerta)",IF(OR(P31>=4,AC31>=15),"Cerrar: marcar sin-respuesta",""))))))
A32: Gestoría Aguilera | B32: Bilbao | C32: Bizkaia | D32: gestoriaaguilera.com | E32: 688729738 | G32: C/Marqués del Puerto 12 3E, 48008 Bilbao | H32: A | I32: frío | J32: alto | K32: Búsqueda web 2026-07-11 | L32: Asesoría desde 30€/mes | M32: pendiente_contacto | Y32: Llamar al teléfono verificado | AC32: =IF(N32="","",TODAY()-N32) | AD32: =IF(N32="","Contactar (día 0)",IF(OR(Q32="sí",M32="rechazado",M32="cliente_pago",M32="sin_respuesta"),"",IF(AND(P32<=1,AC32>=3),"Seguimiento 1 (mismo canal)",IF(AND(P32<=2,AC32>=7),"Seguimiento 2 (canal distinto)",IF(AND(P32<=3,AC32>=12),"Seguimiento 3 (último, ofrece cerrar la puerta)",IF(OR(P32>=4,AC32>=15),"Cerrar: marcar sin-respuesta",""))))))
A33: Gestoría Gabiola | B33: Bilbao | C33: Bizkaia | D33: gestoriagabiola.com | E33: 944444324 | F33: info@gestoriagabiola.com | G33: Calle Alcalde Felipe Uhagón, 9, planta 5, 48010 Bilbao | H33: B | I33: frío | J33: medio | K33: Búsqueda web 2026-07-11 | M33: pendiente_contacto | Y33: Contactar por email o teléfono | AC33: =IF(N33="","",TODAY()-N33) | AD33: =IF(N33="","Contactar (día 0)",IF(OR(Q33="sí",M33="rechazado",M33="cliente_pago",M33="sin_respuesta"),"",IF(AND(P33<=1,AC33>=3),"Seguimiento 1 (mismo canal)",IF(AND(P33<=2,AC33>=7),"Seguimiento 2 (canal distinto)",IF(AND(P33<=3,AC33>=12),"Seguimiento 3 (último, ofrece cerrar la puerta)",IF(OR(P33>=4,AC33>=15),"Cerrar: marcar sin-respuesta",""))))))
A34: Gestoría Galarza | B34: Bilbao | C34: Bizkaia | D34: gestoriagalarza.com | G34: Alameda Recalde, 61, 48010 Bilbao | H34: B | I34: frío | J34: medio | K34: Búsqueda web 2026-07-11 | M34: pendiente_contacto | Y34: Verificar teléfono/email en su web antes de contactar | AC34: =IF(N34="","",TODAY()-N34) | AD34: =IF(N34="","Contactar (día 0)",IF(OR(Q34="sí",M34="rechazado",M34="cliente_pago",M34="sin_respuesta"),"",IF(AND(P34<=1,AC34>=3),"Seguimiento 1 (mismo canal)",IF(AND(P34<=2,AC34>=7),"Seguimiento 2 (canal distinto)",IF(AND(P34<=3,AC34>=12),"Seguimiento 3 (último, ofrece cerrar la puerta)",IF(OR(P34>=4,AC34>=15),"Cerrar: marcar sin-respuesta",""))))))
A35: Gestoría e Madrid | B35: Madrid | C35: Madrid | D35: gestoriaemadrid.com | E35: 914458632 | G35: C/ General Álvarez de Castro, 41, Madrid | H35: A | I35: frío | J35: alto | K35: Búsqueda web 2026-07-11 | L35: Especialista en alta de autónomos, constitución de empresas, Renta | M35: pendiente_contacto | Y35: Llamar al teléfono verificado | AC35: =IF(N35="","",TODAY()-N35) | AD35: =IF(N35="","Contactar (día 0)",IF(OR(Q35="sí",M35="rechazado",M35="cliente_pago",M35="sin_respuesta"),"",IF(AND(P35<=1,AC35>=3),"Seguimiento 1 (mismo canal)",IF(AND(P35<=2,AC35>=7),"Seguimiento 2 (canal distinto)",IF(AND(P35<=3,AC35>=12),"Seguimiento 3 (último, ofrece cerrar la puerta)",IF(OR(P35>=4,AC35>=15),"Cerrar: marcar sin-respuesta",""))))))
A36: MZG Asesores | B36: Madrid | C36: Madrid | D36: mzgasesores.es | E36: 915650904 | H36: B | I36: frío | J36: medio | K36: Búsqueda web 2026-07-11 | L36: Externalización de contabilidad, fiscalidad y laboral | M36: pendiente_contacto | Y36: Llamar al teléfono verificado | AC36: =IF(N36="","",TODAY()-N36) | AD36: =IF(N36="","Contactar (día 0)",IF(OR(Q36="sí",M36="rechazado",M36="cliente_pago",M36="sin_respuesta"),"",IF(AND(P36<=1,AC36>=3),"Seguimiento 1 (mismo canal)",IF(AND(P36<=2,AC36>=7),"Seguimiento 2 (canal distinto)",IF(AND(P36<=3,AC36>=12),"Seguimiento 3 (último, ofrece cerrar la puerta)",IF(OR(P36>=4,AC36>=15),"Cerrar: marcar sin-respuesta",""))))))
A37: Gestión de Autónomos | B37: Madrid | C37: Madrid | D37: gestiondeautonomos.es | E37: 913839652 | G37: Av. del Monasterio de Silos, 13, Local Photofilms, 28049 Madrid | H37: A | I37: frío | J37: alto | K37: Búsqueda web 2026-07-11 | M37: pendiente_contacto | Y37: Llamar al teléfono verificado | AC37: =IF(N37="","",TODAY()-N37) | AD37: =IF(N37="","Contactar (día 0)",IF(OR(Q37="sí",M37="rechazado",M37="cliente_pago",M37="sin_respuesta"),"",IF(AND(P37<=1,AC37>=3),"Seguimiento 1 (mismo canal)",IF(AND(P37<=2,AC37>=7),"Seguimiento 2 (canal distinto)",IF(AND(P37<=3,AC37>=12),"Seguimiento 3 (último, ofrece cerrar la puerta)",IF(OR(P37>=4,AC37>=15),"Cerrar: marcar sin-respuesta",""))))))
A38: Gestoralia | B38: Madrid | C38: Madrid | D38: gestoralia.net | E38: 913916990 | H38: A | I38: frío | J38: alto | K38: Búsqueda web 2026-07-11 | L38: Gestoría de autónomos en Madrid | M38: pendiente_contacto | Y38: Llamar al teléfono verificado | AC38: =IF(N38="","",TODAY()-N38) | AD38: =IF(N38="","Contactar (día 0)",IF(OR(Q38="sí",M38="rechazado",M38="cliente_pago",M38="sin_respuesta"),"",IF(AND(P38<=1,AC38>=3),"Seguimiento 1 (mismo canal)",IF(AND(P38<=2,AC38>=7),"Seguimiento 2 (canal distinto)",IF(AND(P38<=3,AC38>=12),"Seguimiento 3 (último, ofrece cerrar la puerta)",IF(OR(P38>=4,AC38>=15),"Cerrar: marcar sin-respuesta",""))))))
A39: GestAlacant | B39: Alicante | C39: Alicante | D39: gestalacant.com | E39: 965920107 | G39: Calle José María Py, 21, 03005 Alicante | H39: B | I39: frío | J39: medio | K39: Búsqueda web 2026-07-11 | M39: pendiente_contacto | Y39: Llamar al teléfono verificado | AC39: =IF(N39="","",TODAY()-N39) | AD39: =IF(N39="","Contactar (día 0)",IF(OR(Q39="sí",M39="rechazado",M39="cliente_pago",M39="sin_respuesta"),"",IF(AND(P39<=1,AC39>=3),"Seguimiento 1 (mismo canal)",IF(AND(P39<=2,AC39>=7),"Seguimiento 2 (canal distinto)",IF(AND(P39<=3,AC39>=12),"Seguimiento 3 (último, ofrece cerrar la puerta)",IF(OR(P39>=4,AC39>=15),"Cerrar: marcar sin-respuesta",""))))))
A40: San Nicolás Asesores | B40: Alicante | C40: Alicante | D40: sannicolasasesores.es | E40: 965922315 | G40: Alicante centro | H40: B | I40: frío | J40: medio | K40: Búsqueda web 2026-07-11 | M40: pendiente_contacto | Y40: Llamar al teléfono verificado | AC40: =IF(N40="","",TODAY()-N40) | AD40: =IF(N40="","Contactar (día 0)",IF(OR(Q40="sí",M40="rechazado",M40="cliente_pago",M40="sin_respuesta"),"",IF(AND(P40<=1,AC40>=3),"Seguimiento 1 (mismo canal)",IF(AND(P40<=2,AC40>=7),"Seguimiento 2 (canal distinto)",IF(AND(P40<=3,AC40>=12),"Seguimiento 3 (último, ofrece cerrar la puerta)",IF(OR(P40>=4,AC40>=15),"Cerrar: marcar sin-respuesta",""))))))
...

Sheet Dashboard
A1: Dashboard — GestorIA (embudo comercial)
A3: Métrica | B3: Valor
A4: Total prospectos en el CRM | B4: =COUNTA(CRM!A2:A56)
A5: Contactos realizados | B5: =COUNTA(CRM!N2:N56)
A6: Respuestas recibidas | B6: =COUNTIF(CRM!Q2:Q56,"sí")
A7: Reuniones / demos agendadas | B7: =COUNTIF(CRM!S2:S56,"sí")
A8: Demos realizadas | B8: =COUNTIF(CRM!T2:T56,"sí")
A9: Pilotos iniciados | B9: =COUNTIF(CRM!U2:U56,"sí")
A10: Clientes de pago | B10: =COUNTIF(CRM!AA2:AA56,"sí")
A11: MRR (€/mes) | B11: =SUMIF(CRM!AA2:AA56,"sí",CRM!AB2:AB56)
A12: Rechazos | B12: =COUNTIF(CRM!V2:V56,"sí")
A14: Tasas de conversión
A15: Contacto → respuesta | B15: =IFERROR(B6/B5,0)
A16: Respuesta → demo | B16: =IFERROR(B8/B6,0)
A17: Demo → piloto | B17: =IFERROR(B9/B8,0)
A18: Piloto → cliente de pago | B18: =IFERROR(B10/B9,0)
A20: Reto de 30 días
A21: Objetivo | B21: Meta | C21: Actual | D21: % cumplido
A22: Conversaciones (respuestas) | B22: 20 | C22: =Dashboard!B6 | D22: =IFERROR(C22/B22,0)
A23: Demos realizadas | B23: 5 | C23: =Dashboard!B8 | D23: =IFERROR(C23/B23,0)
A24: Pilotos iniciados | B24: 3 | C24: =Dashboard!B9 | D24: =IFERROR(C24/B24,0)
A25: Clientes de pago | B25: 1 | C25: =Dashboard!B10 | D25: =IFERROR(C25/B25,0)
